[2024-06-26T23:24:21.772+0000] {local_task_job_runner.py:120} INFO - ::group::Pre task execution logs
[2024-06-26T23:24:21.793+0000] {taskinstance.py:2076} INFO - Dependencies all met for dep_context=non-requeueable deps ti=<TaskInstance: data_backup_to_gcs.upload_to_gcs manual__2024-06-26T23:24:00.424534+00:00 [queued]>
[2024-06-26T23:24:21.799+0000] {taskinstance.py:2076} INFO - Dependencies all met for dep_context=requeueable deps ti=<TaskInstance: data_backup_to_gcs.upload_to_gcs manual__2024-06-26T23:24:00.424534+00:00 [queued]>
[2024-06-26T23:24:21.799+0000] {taskinstance.py:2306} INFO - Starting attempt 1 of 2
[2024-06-26T23:24:21.807+0000] {taskinstance.py:2330} INFO - Executing <Task(BashOperator): upload_to_gcs> on 2024-06-26 23:24:00.424534+00:00
[2024-06-26T23:24:21.815+0000] {logging_mixin.py:188} WARNING - /home/***/.local/lib/python3.12/site-packages/***/task/task_runner/standard_task_runner.py:61 DeprecationWarning: This process (pid=672) is multi-threaded, use of fork() may lead to deadlocks in the child.
[2024-06-26T23:24:21.815+0000] {standard_task_runner.py:63} INFO - Started process 678 to run task
[2024-06-26T23:24:21.814+0000] {standard_task_runner.py:90} INFO - Running: ['***', 'tasks', 'run', 'data_backup_to_gcs', 'upload_to_gcs', 'manual__2024-06-26T23:24:00.424534+00:00', '--job-id', '61', '--raw', '--subdir', 'DAGS_FOLDER/to_gcs.py', '--cfg-path', '/tmp/tmptzi9nop3']
[2024-06-26T23:24:21.815+0000] {standard_task_runner.py:91} INFO - Job 61: Subtask upload_to_gcs
[2024-06-26T23:24:21.846+0000] {task_command.py:426} INFO - Running <TaskInstance: data_backup_to_gcs.upload_to_gcs manual__2024-06-26T23:24:00.424534+00:00 [running]> on host 1156a65a130e
[2024-06-26T23:24:21.904+0000] {taskinstance.py:2648} INFO - Exporting env vars: AIRFLOW_CTX_DAG_OWNER='***' AIRFLOW_CTX_DAG_ID='data_backup_to_gcs' AIRFLOW_CTX_TASK_ID='upload_to_gcs' AIRFLOW_CTX_EXECUTION_DATE='2024-06-26T23:24:00.424534+00:00' AIRFLOW_CTX_TRY_NUMBER='1' AIRFLOW_CTX_DAG_RUN_ID='manual__2024-06-26T23:24:00.424534+00:00'
[2024-06-26T23:24:21.905+0000] {taskinstance.py:430} INFO - ::endgroup::
[2024-06-26T23:24:21.916+0000] {subprocess.py:63} INFO - Tmp dir root location: /tmp
[2024-06-26T23:24:21.916+0000] {subprocess.py:75} INFO - Running command: ['/usr/bin/bash', '-c', 'gsutil cp -r /opt/***/dags/backup.sql gs://test/backup.sql']
[2024-06-26T23:24:21.925+0000] {subprocess.py:86} INFO - Output:
[2024-06-26T23:24:21.926+0000] {subprocess.py:93} INFO - /usr/bin/bash: line 1: gsutil: command not found
[2024-06-26T23:24:21.926+0000] {subprocess.py:97} INFO - Command exited with return code 127
[2024-06-26T23:24:21.927+0000] {taskinstance.py:441} INFO - ::group::Post task execution logs
[2024-06-26T23:24:21.937+0000] {taskinstance.py:2905} ERROR - Task failed with exception
Traceback (most recent call last):
  File "/home/airflow/.local/lib/python3.12/site-packages/airflow/models/taskinstance.py", line 465, in _execute_task
    result = _execute_callable(context=context, **execute_callable_kwargs)
             ^^^^^^^^^^^^^^^^^^^^^^^^^^^^^^^^^^^^^^^^^^^^^^^^^^^^^^^^^^^^^
  File "/home/airflow/.local/lib/python3.12/site-packages/airflow/models/taskinstance.py", line 432, in _execute_callable
    return execute_callable(context=context, **execute_callable_kwargs)
           ^^^^^^^^^^^^^^^^^^^^^^^^^^^^^^^^^^^^^^^^^^^^^^^^^^^^^^^^^^^^
  File "/home/airflow/.local/lib/python3.12/site-packages/airflow/models/baseoperator.py", line 401, in wrapper
    return func(self, *args, **kwargs)
           ^^^^^^^^^^^^^^^^^^^^^^^^^^^
  File "/home/airflow/.local/lib/python3.12/site-packages/airflow/operators/bash.py", line 243, in execute
    raise AirflowException(
airflow.exceptions.AirflowException: Bash command failed. The command returned a non-zero exit code 127.
[2024-06-26T23:24:21.941+0000] {taskinstance.py:1206} INFO - Marking task as UP_FOR_RETRY. dag_id=data_backup_to_gcs, task_id=upload_to_gcs, run_id=manual__2024-06-26T23:24:00.424534+00:00, execution_date=20240626T232400, start_date=20240626T232421, end_date=20240626T232421
[2024-06-26T23:24:21.955+0000] {standard_task_runner.py:110} ERROR - Failed to execute job 61 for task upload_to_gcs (Bash command failed. The command returned a non-zero exit code 127.; 678)
[2024-06-26T23:24:21.988+0000] {local_task_job_runner.py:240} INFO - Task exited with return code 1
[2024-06-26T23:24:22.011+0000] {taskinstance.py:3503} INFO - 0 downstream tasks scheduled from follow-on schedule check
[2024-06-26T23:24:22.013+0000] {local_task_job_runner.py:222} INFO - ::endgroup::
