[2024-06-27T03:43:28.952+0000] {local_task_job_runner.py:120} INFO - ::group::Pre task execution logs
[2024-06-27T03:43:28.979+0000] {taskinstance.py:2076} INFO - Dependencies all met for dep_context=non-requeueable deps ti=<TaskInstance: data_transfer_to_gcs.upload_to_gcs manual__2024-06-27T03:38:09.060835+00:00 [queued]>
[2024-06-27T03:43:28.989+0000] {taskinstance.py:2076} INFO - Dependencies all met for dep_context=requeueable deps ti=<TaskInstance: data_transfer_to_gcs.upload_to_gcs manual__2024-06-27T03:38:09.060835+00:00 [queued]>
[2024-06-27T03:43:28.989+0000] {taskinstance.py:2306} INFO - Starting attempt 2 of 2
[2024-06-27T03:43:28.998+0000] {taskinstance.py:2330} INFO - Executing <Task(LocalFilesystemToGCSOperator): upload_to_gcs> on 2024-06-27 03:38:09.060835+00:00
[2024-06-27T03:43:29.010+0000] {standard_task_runner.py:90} INFO - Running: ['***', 'tasks', 'run', 'data_transfer_to_gcs', 'upload_to_gcs', 'manual__2024-06-27T03:38:09.060835+00:00', '--job-id', '121', '--raw', '--subdir', 'DAGS_FOLDER/to_gcs.py', '--cfg-path', '/tmp/tmpknqr2aqa']
[2024-06-27T03:43:29.012+0000] {standard_task_runner.py:91} INFO - Job 121: Subtask upload_to_gcs
[2024-06-27T03:43:29.014+0000] {logging_mixin.py:188} WARNING - /home/***/.local/lib/python3.12/site-packages/***/task/task_runner/standard_task_runner.py:61 DeprecationWarning: This process (pid=1608) is multi-threaded, use of fork() may lead to deadlocks in the child.
[2024-06-27T03:43:29.015+0000] {standard_task_runner.py:63} INFO - Started process 1610 to run task
[2024-06-27T03:43:29.060+0000] {task_command.py:426} INFO - Running <TaskInstance: data_transfer_to_gcs.upload_to_gcs manual__2024-06-27T03:38:09.060835+00:00 [running]> on host 4d14308606fb
[2024-06-27T03:43:29.160+0000] {taskinstance.py:2648} INFO - Exporting env vars: AIRFLOW_CTX_DAG_OWNER='***' AIRFLOW_CTX_DAG_ID='data_transfer_to_gcs' AIRFLOW_CTX_TASK_ID='upload_to_gcs' AIRFLOW_CTX_EXECUTION_DATE='2024-06-27T03:38:09.060835+00:00' AIRFLOW_CTX_TRY_NUMBER='2' AIRFLOW_CTX_DAG_RUN_ID='manual__2024-06-27T03:38:09.060835+00:00'
[2024-06-27T03:43:29.162+0000] {taskinstance.py:430} INFO - ::endgroup::
[2024-06-27T03:43:29.202+0000] {connection.py:274} WARNING - Connection schemes (type: google_cloud_platform) shall not contain '_' according to RFC3986.
[2024-06-27T03:43:29.211+0000] {base.py:84} INFO - Using connection ID 'google_cloud_default' for task execution.
[2024-06-27T03:43:51.783+0000] {gcs.py:515} ERROR - Upload attempt of object: data/exported_data.csv from data/exported_data.csv has failed. Attempt: 1, max 1.
[2024-06-27T03:43:51.783+0000] {taskinstance.py:441} INFO - ::group::Post task execution logs
[2024-06-27T03:43:51.784+0000] {taskinstance.py:2905} ERROR - Task failed with exception
Traceback (most recent call last):
  File "/home/airflow/.local/lib/python3.12/site-packages/google/cloud/storage/blob.py", line 2637, in _prep_and_do_upload
    created_json = self._do_upload(
                   ^^^^^^^^^^^^^^^^
  File "/home/airflow/.local/lib/python3.12/site-packages/google/cloud/storage/blob.py", line 2443, in _do_upload
    response = self._do_multipart_upload(
               ^^^^^^^^^^^^^^^^^^^^^^^^^^
  File "/home/airflow/.local/lib/python3.12/site-packages/google/cloud/storage/blob.py", line 1956, in _do_multipart_upload
    response = upload.transmit(
               ^^^^^^^^^^^^^^^^
  File "/home/airflow/.local/lib/python3.12/site-packages/google/resumable_media/requests/upload.py", line 153, in transmit
    return _request_helpers.wait_and_retry(
           ^^^^^^^^^^^^^^^^^^^^^^^^^^^^^^^^
  File "/home/airflow/.local/lib/python3.12/site-packages/google/resumable_media/requests/_request_helpers.py", line 155, in wait_and_retry
    response = func()
               ^^^^^^
  File "/home/airflow/.local/lib/python3.12/site-packages/google/resumable_media/requests/upload.py", line 149, in retriable_request
    self._process_response(result)
  File "/home/airflow/.local/lib/python3.12/site-packages/google/resumable_media/_upload.py", line 125, in _process_response
    _helpers.require_status_code(response, (http.client.OK,), self._get_status_code)
  File "/home/airflow/.local/lib/python3.12/site-packages/google/resumable_media/_helpers.py", line 108, in require_status_code
    raise common.InvalidResponse(
google.resumable_media.common.InvalidResponse: ('Request failed with status code', 403, 'Expected one of', 200)

During handling of the above exception, another exception occurred:

Traceback (most recent call last):
  File "/home/airflow/.local/lib/python3.12/site-packages/airflow/models/taskinstance.py", line 465, in _execute_task
    result = _execute_callable(context=context, **execute_callable_kwargs)
             ^^^^^^^^^^^^^^^^^^^^^^^^^^^^^^^^^^^^^^^^^^^^^^^^^^^^^^^^^^^^^
  File "/home/airflow/.local/lib/python3.12/site-packages/airflow/models/taskinstance.py", line 432, in _execute_callable
    return execute_callable(context=context, **execute_callable_kwargs)
           ^^^^^^^^^^^^^^^^^^^^^^^^^^^^^^^^^^^^^^^^^^^^^^^^^^^^^^^^^^^^
  File "/home/airflow/.local/lib/python3.12/site-packages/airflow/models/baseoperator.py", line 401, in wrapper
    return func(self, *args, **kwargs)
           ^^^^^^^^^^^^^^^^^^^^^^^^^^^
  File "/home/airflow/.local/lib/python3.12/site-packages/airflow/providers/google/cloud/transfers/local_to_gcs.py", line 111, in execute
    hook.upload(
  File "/home/airflow/.local/lib/python3.12/site-packages/airflow/providers/google/cloud/hooks/gcs.py", line 554, in upload
    _call_with_retry(
  File "/home/airflow/.local/lib/python3.12/site-packages/airflow/providers/google/cloud/hooks/gcs.py", line 522, in _call_with_retry
    raise e
  File "/home/airflow/.local/lib/python3.12/site-packages/airflow/providers/google/cloud/hooks/gcs.py", line 512, in _call_with_retry
    f()
  File "/home/airflow/.local/lib/python3.12/site-packages/google/cloud/storage/blob.py", line 2959, in upload_from_filename
    self._handle_filename_and_upload(
  File "/home/airflow/.local/lib/python3.12/site-packages/google/cloud/storage/blob.py", line 2829, in _handle_filename_and_upload
    self._prep_and_do_upload(
  File "/home/airflow/.local/lib/python3.12/site-packages/google/cloud/storage/blob.py", line 2655, in _prep_and_do_upload
    _raise_from_invalid_response(exc)
  File "/home/airflow/.local/lib/python3.12/site-packages/google/cloud/storage/blob.py", line 4847, in _raise_from_invalid_response
    raise exceptions.from_http_status(response.status_code, message, response=response)
google.api_core.exceptions.Forbidden: 403 POST https://storage.googleapis.com/upload/storage/v1/b/testing/o?uploadType=multipart: {
  "error": {
    "code": 403,
    "message": "airflow-svc@starlit-cocoa-423615-r6.iam.gserviceaccount.com does not have storage.objects.create access to the Google Cloud Storage object. Permission 'storage.objects.create' denied on resource (or it may not exist).",
    "errors": [
      {
        "message": "airflow-svc@starlit-cocoa-423615-r6.iam.gserviceaccount.com does not have storage.objects.create access to the Google Cloud Storage object. Permission 'storage.objects.create' denied on resource (or it may not exist).",
        "domain": "global",
        "reason": "forbidden"
      }
    ]
  }
}
: ('Request failed with status code', 403, 'Expected one of', <HTTPStatus.OK: 200>)
[2024-06-27T03:43:51.800+0000] {taskinstance.py:1206} INFO - Marking task as FAILED. dag_id=data_transfer_to_gcs, task_id=upload_to_gcs, run_id=manual__2024-06-27T03:38:09.060835+00:00, execution_date=20240627T033809, start_date=20240627T034328, end_date=20240627T034351
[2024-06-27T03:43:51.812+0000] {standard_task_runner.py:110} ERROR - Failed to execute job 121 for task upload_to_gcs (403 POST https://storage.googleapis.com/upload/storage/v1/b/testing/o?uploadType=multipart: {
  "error": {
    "code": 403,
    "message": "airflow-svc@starlit-cocoa-423615-r6.iam.gserviceaccount.com does not have storage.objects.create access to the Google Cloud Storage object. Permission 'storage.objects.create' denied on resource (or it may not exist).",
    "errors": [
      {
        "message": "airflow-svc@starlit-cocoa-423615-r6.iam.gserviceaccount.com does not have storage.objects.create access to the Google Cloud Storage object. Permission 'storage.objects.create' denied on resource (or it may not exist).",
        "domain": "global",
        "reason": "forbidden"
      }
    ]
  }
}
: ('Request failed with status code', 403, 'Expected one of', <HTTPStatus.OK: 200>); 1610)
[2024-06-27T03:43:51.828+0000] {local_task_job_runner.py:240} INFO - Task exited with return code 1
[2024-06-27T03:43:51.854+0000] {taskinstance.py:3503} INFO - 0 downstream tasks scheduled from follow-on schedule check
[2024-06-27T03:43:51.857+0000] {local_task_job_runner.py:222} INFO - ::endgroup::
