[2024-06-27T03:20:46.635+0000] {local_task_job_runner.py:120} INFO - ::group::Pre task execution logs
[2024-06-27T03:20:46.646+0000] {taskinstance.py:2076} INFO - Dependencies all met for dep_context=non-requeueable deps ti=<TaskInstance: data_transfer_to_gcs.upload_to_gcs manual__2024-06-27T03:15:35.204330+00:00 [queued]>
[2024-06-27T03:20:46.652+0000] {taskinstance.py:2076} INFO - Dependencies all met for dep_context=requeueable deps ti=<TaskInstance: data_transfer_to_gcs.upload_to_gcs manual__2024-06-27T03:15:35.204330+00:00 [queued]>
[2024-06-27T03:20:46.652+0000] {taskinstance.py:2306} INFO - Starting attempt 2 of 2
[2024-06-27T03:20:46.659+0000] {taskinstance.py:2330} INFO - Executing <Task(LocalFilesystemToGCSOperator): upload_to_gcs> on 2024-06-27 03:15:35.204330+00:00
[2024-06-27T03:20:46.667+0000] {logging_mixin.py:188} WARNING - /home/***/.local/lib/python3.12/site-packages/***/task/task_runner/standard_task_runner.py:61 DeprecationWarning: This process (pid=1047) is multi-threaded, use of fork() may lead to deadlocks in the child.
[2024-06-27T03:20:46.667+0000] {standard_task_runner.py:63} INFO - Started process 1049 to run task
[2024-06-27T03:20:46.666+0000] {standard_task_runner.py:90} INFO - Running: ['***', 'tasks', 'run', 'data_transfer_to_gcs', 'upload_to_gcs', 'manual__2024-06-27T03:15:35.204330+00:00', '--job-id', '112', '--raw', '--subdir', 'DAGS_FOLDER/to_gcs.py', '--cfg-path', '/tmp/tmpio2rqgd5']
[2024-06-27T03:20:46.668+0000] {standard_task_runner.py:91} INFO - Job 112: Subtask upload_to_gcs
[2024-06-27T03:20:46.705+0000] {task_command.py:426} INFO - Running <TaskInstance: data_transfer_to_gcs.upload_to_gcs manual__2024-06-27T03:15:35.204330+00:00 [running]> on host 4d14308606fb
[2024-06-27T03:20:46.797+0000] {taskinstance.py:2648} INFO - Exporting env vars: AIRFLOW_CTX_DAG_OWNER='***' AIRFLOW_CTX_DAG_ID='data_transfer_to_gcs' AIRFLOW_CTX_TASK_ID='upload_to_gcs' AIRFLOW_CTX_EXECUTION_DATE='2024-06-27T03:15:35.204330+00:00' AIRFLOW_CTX_TRY_NUMBER='2' AIRFLOW_CTX_DAG_RUN_ID='manual__2024-06-27T03:15:35.204330+00:00'
[2024-06-27T03:20:46.798+0000] {taskinstance.py:430} INFO - ::endgroup::
[2024-06-27T03:20:46.813+0000] {connection.py:274} WARNING - Connection schemes (type: google_cloud_platform) shall not contain '_' according to RFC3986.
[2024-06-27T03:20:46.817+0000] {base.py:84} INFO - Using connection ID 'google_cloud_default' for task execution.
[2024-06-27T03:21:00.697+0000] {taskinstance.py:441} INFO - ::group::Post task execution logs
[2024-06-27T03:21:00.698+0000] {taskinstance.py:2905} ERROR - Task failed with exception
Traceback (most recent call last):
  File "/home/airflow/.local/lib/python3.12/site-packages/urllib3/connection.py", line 198, in _new_conn
    sock = connection.create_connection(
           ^^^^^^^^^^^^^^^^^^^^^^^^^^^^^
  File "/home/airflow/.local/lib/python3.12/site-packages/urllib3/util/connection.py", line 60, in create_connection
    for res in socket.getaddrinfo(host, port, family, socket.SOCK_STREAM):
               ^^^^^^^^^^^^^^^^^^^^^^^^^^^^^^^^^^^^^^^^^^^^^^^^^^^^^^^^^^
  File "/usr/local/lib/python3.12/socket.py", line 964, in getaddrinfo
    for res in _socket.getaddrinfo(host, port, family, type, proto, flags):
               ^^^^^^^^^^^^^^^^^^^^^^^^^^^^^^^^^^^^^^^^^^^^^^^^^^^^^^^^^^^
socket.gaierror: [Errno -3] Temporary failure in name resolution

The above exception was the direct cause of the following exception:

Traceback (most recent call last):
  File "/home/airflow/.local/lib/python3.12/site-packages/urllib3/connectionpool.py", line 793, in urlopen
    response = self._make_request(
               ^^^^^^^^^^^^^^^^^^^
  File "/home/airflow/.local/lib/python3.12/site-packages/urllib3/connectionpool.py", line 491, in _make_request
    raise new_e
  File "/home/airflow/.local/lib/python3.12/site-packages/urllib3/connectionpool.py", line 467, in _make_request
    self._validate_conn(conn)
  File "/home/airflow/.local/lib/python3.12/site-packages/urllib3/connectionpool.py", line 1099, in _validate_conn
    conn.connect()
  File "/home/airflow/.local/lib/python3.12/site-packages/urllib3/connection.py", line 616, in connect
    self.sock = sock = self._new_conn()
                       ^^^^^^^^^^^^^^^^
  File "/home/airflow/.local/lib/python3.12/site-packages/urllib3/connection.py", line 205, in _new_conn
    raise NameResolutionError(self.host, self, e) from e
urllib3.exceptions.NameResolutionError: <urllib3.connection.HTTPSConnection object at 0x7ecb5491d4f0>: Failed to resolve 'storage.googleapis.com' ([Errno -3] Temporary failure in name resolution)

The above exception was the direct cause of the following exception:

Traceback (most recent call last):
  File "/home/airflow/.local/lib/python3.12/site-packages/requests/adapters.py", line 486, in send
    resp = conn.urlopen(
           ^^^^^^^^^^^^^
  File "/home/airflow/.local/lib/python3.12/site-packages/urllib3/connectionpool.py", line 847, in urlopen
    retries = retries.increment(
              ^^^^^^^^^^^^^^^^^^
  File "/home/airflow/.local/lib/python3.12/site-packages/urllib3/util/retry.py", line 515, in increment
    raise MaxRetryError(_pool, url, reason) from reason  # type: ignore[arg-type]
    ^^^^^^^^^^^^^^^^^^^^^^^^^^^^^^^^^^^^^^^^^^^^^^^^^^^
urllib3.exceptions.MaxRetryError: HTTPSConnectionPool(host='storage.googleapis.com', port=443): Max retries exceeded with url: /upload/storage/v1/b/testing/o?uploadType=multipart (Caused by NameResolutionError("<urllib3.connection.HTTPSConnection object at 0x7ecb5491d4f0>: Failed to resolve 'storage.googleapis.com' ([Errno -3] Temporary failure in name resolution)"))

During handling of the above exception, another exception occurred:

Traceback (most recent call last):
  File "/home/airflow/.local/lib/python3.12/site-packages/airflow/models/taskinstance.py", line 465, in _execute_task
    result = _execute_callable(context=context, **execute_callable_kwargs)
             ^^^^^^^^^^^^^^^^^^^^^^^^^^^^^^^^^^^^^^^^^^^^^^^^^^^^^^^^^^^^^
  File "/home/airflow/.local/lib/python3.12/site-packages/airflow/models/taskinstance.py", line 432, in _execute_callable
    return execute_callable(context=context, **execute_callable_kwargs)
           ^^^^^^^^^^^^^^^^^^^^^^^^^^^^^^^^^^^^^^^^^^^^^^^^^^^^^^^^^^^^
  File "/home/airflow/.local/lib/python3.12/site-packages/airflow/models/baseoperator.py", line 401, in wrapper
    return func(self, *args, **kwargs)
           ^^^^^^^^^^^^^^^^^^^^^^^^^^^
  File "/home/airflow/.local/lib/python3.12/site-packages/airflow/providers/google/cloud/transfers/local_to_gcs.py", line 111, in execute
    hook.upload(
  File "/home/airflow/.local/lib/python3.12/site-packages/airflow/providers/google/cloud/hooks/gcs.py", line 554, in upload
    _call_with_retry(
  File "/home/airflow/.local/lib/python3.12/site-packages/airflow/providers/google/cloud/hooks/gcs.py", line 512, in _call_with_retry
    f()
  File "/home/airflow/.local/lib/python3.12/site-packages/google/cloud/storage/blob.py", line 2959, in upload_from_filename
    self._handle_filename_and_upload(
  File "/home/airflow/.local/lib/python3.12/site-packages/google/cloud/storage/blob.py", line 2829, in _handle_filename_and_upload
    self._prep_and_do_upload(
  File "/home/airflow/.local/lib/python3.12/site-packages/google/cloud/storage/blob.py", line 2637, in _prep_and_do_upload
    created_json = self._do_upload(
                   ^^^^^^^^^^^^^^^^
  File "/home/airflow/.local/lib/python3.12/site-packages/google/cloud/storage/blob.py", line 2443, in _do_upload
    response = self._do_multipart_upload(
               ^^^^^^^^^^^^^^^^^^^^^^^^^^
  File "/home/airflow/.local/lib/python3.12/site-packages/google/cloud/storage/blob.py", line 1956, in _do_multipart_upload
    response = upload.transmit(
               ^^^^^^^^^^^^^^^^
  File "/home/airflow/.local/lib/python3.12/site-packages/google/resumable_media/requests/upload.py", line 153, in transmit
    return _request_helpers.wait_and_retry(
           ^^^^^^^^^^^^^^^^^^^^^^^^^^^^^^^^
  File "/home/airflow/.local/lib/python3.12/site-packages/google/resumable_media/requests/_request_helpers.py", line 178, in wait_and_retry
    raise error
  File "/home/airflow/.local/lib/python3.12/site-packages/google/resumable_media/requests/_request_helpers.py", line 155, in wait_and_retry
    response = func()
               ^^^^^^
  File "/home/airflow/.local/lib/python3.12/site-packages/google/resumable_media/requests/upload.py", line 145, in retriable_request
    result = transport.request(
             ^^^^^^^^^^^^^^^^^^
  File "/home/airflow/.local/lib/python3.12/site-packages/google/auth/transport/requests.py", line 541, in request
    response = super(AuthorizedSession, self).request(
               ^^^^^^^^^^^^^^^^^^^^^^^^^^^^^^^^^^^^^^^
  File "/home/airflow/.local/lib/python3.12/site-packages/requests/sessions.py", line 589, in request
    resp = self.send(prep, **send_kwargs)
           ^^^^^^^^^^^^^^^^^^^^^^^^^^^^^^
  File "/home/airflow/.local/lib/python3.12/site-packages/requests/sessions.py", line 703, in send
    r = adapter.send(request, **kwargs)
        ^^^^^^^^^^^^^^^^^^^^^^^^^^^^^^^
  File "/home/airflow/.local/lib/python3.12/site-packages/requests/adapters.py", line 519, in send
    raise ConnectionError(e, request=request)
requests.exceptions.ConnectionError: HTTPSConnectionPool(host='storage.googleapis.com', port=443): Max retries exceeded with url: /upload/storage/v1/b/testing/o?uploadType=multipart (Caused by NameResolutionError("<urllib3.connection.HTTPSConnection object at 0x7ecb5491d4f0>: Failed to resolve 'storage.googleapis.com' ([Errno -3] Temporary failure in name resolution)"))
[2024-06-27T03:21:00.715+0000] {taskinstance.py:1206} INFO - Marking task as FAILED. dag_id=data_transfer_to_gcs, task_id=upload_to_gcs, run_id=manual__2024-06-27T03:15:35.204330+00:00, execution_date=20240627T031535, start_date=20240627T032046, end_date=20240627T032100
[2024-06-27T03:21:00.733+0000] {standard_task_runner.py:110} ERROR - Failed to execute job 112 for task upload_to_gcs (HTTPSConnectionPool(host='storage.googleapis.com', port=443): Max retries exceeded with url: /upload/storage/v1/b/testing/o?uploadType=multipart (Caused by NameResolutionError("<urllib3.connection.HTTPSConnection object at 0x7ecb5491d4f0>: Failed to resolve 'storage.googleapis.com' ([Errno -3] Temporary failure in name resolution)")); 1049)
[2024-06-27T03:21:00.746+0000] {local_task_job_runner.py:240} INFO - Task exited with return code 1
[2024-06-27T03:21:00.768+0000] {taskinstance.py:3503} INFO - 0 downstream tasks scheduled from follow-on schedule check
[2024-06-27T03:21:00.770+0000] {local_task_job_runner.py:222} INFO - ::endgroup::
