[2024-06-26T23:24:01.987+0000] {scheduler_job_runner.py:769} ERROR - Executor reports task instance <TaskInstance: data_backup_to_gcs.backup_mysql manual__2024-06-26T23:24:00.424534+00:00 [queued]> finished (failed) although the task says it's queued. (Info: None) Was the task killed externally?
