[2024-06-26T15:35:14.914+0000] {local_task_job_runner.py:120} INFO - ::group::Pre task execution logs
[2024-06-26T15:35:14.934+0000] {taskinstance.py:2076} INFO - Dependencies all met for dep_context=non-requeueable deps ti=<TaskInstance: data_transfer_to_mysql.load_data_to_mysql manual__2024-06-26T15:35:14.290955+00:00 [queued]>
[2024-06-26T15:35:14.940+0000] {taskinstance.py:2076} INFO - Dependencies all met for dep_context=requeueable deps ti=<TaskInstance: data_transfer_to_mysql.load_data_to_mysql manual__2024-06-26T15:35:14.290955+00:00 [queued]>
[2024-06-26T15:35:14.940+0000] {taskinstance.py:2306} INFO - Starting attempt 1 of 2
[2024-06-26T15:35:14.947+0000] {taskinstance.py:2330} INFO - Executing <Task(PythonOperator): load_data_to_mysql> on 2024-06-26 15:35:14.290955+00:00
[2024-06-26T15:35:14.954+0000] {logging_mixin.py:188} WARNING - /home/***/.local/lib/python3.12/site-packages/***/task/task_runner/standard_task_runner.py:61 DeprecationWarning: This process (pid=666) is multi-threaded, use of fork() may lead to deadlocks in the child.
[2024-06-26T15:35:14.955+0000] {standard_task_runner.py:63} INFO - Started process 668 to run task
[2024-06-26T15:35:14.954+0000] {standard_task_runner.py:90} INFO - Running: ['***', 'tasks', 'run', 'data_transfer_to_mysql', 'load_data_to_mysql', 'manual__2024-06-26T15:35:14.290955+00:00', '--job-id', '35', '--raw', '--subdir', 'DAGS_FOLDER/data_transfer_dag.py', '--cfg-path', '/tmp/tmp38b7ndga']
[2024-06-26T15:35:14.955+0000] {standard_task_runner.py:91} INFO - Job 35: Subtask load_data_to_mysql
[2024-06-26T15:35:14.987+0000] {task_command.py:426} INFO - Running <TaskInstance: data_transfer_to_mysql.load_data_to_mysql manual__2024-06-26T15:35:14.290955+00:00 [running]> on host fa313e9b9eb9
[2024-06-26T15:35:15.042+0000] {taskinstance.py:2648} INFO - Exporting env vars: AIRFLOW_CTX_DAG_OWNER='***' AIRFLOW_CTX_DAG_ID='data_transfer_to_mysql' AIRFLOW_CTX_TASK_ID='load_data_to_mysql' AIRFLOW_CTX_EXECUTION_DATE='2024-06-26T15:35:14.290955+00:00' AIRFLOW_CTX_TRY_NUMBER='1' AIRFLOW_CTX_DAG_RUN_ID='manual__2024-06-26T15:35:14.290955+00:00'
[2024-06-26T15:35:15.043+0000] {taskinstance.py:430} INFO - ::endgroup::
[2024-06-26T15:35:15.060+0000] {base.py:84} INFO - Using connection ID 'mysql_conn' for task execution.
[2024-06-26T15:35:15.083+0000] {taskinstance.py:441} INFO - ::group::Post task execution logs
[2024-06-26T15:35:15.083+0000] {taskinstance.py:2905} ERROR - Task failed with exception
Traceback (most recent call last):
  File "/home/airflow/.local/lib/python3.12/site-packages/sqlalchemy/engine/base.py", line 1910, in _execute_context
    self.dialect.do_execute(
  File "/home/airflow/.local/lib/python3.12/site-packages/sqlalchemy/engine/default.py", line 736, in do_execute
    cursor.execute(statement, parameters)
  File "/home/airflow/.local/lib/python3.12/site-packages/MySQLdb/cursors.py", line 179, in execute
    res = self._query(mogrified_query)
          ^^^^^^^^^^^^^^^^^^^^^^^^^^^^
  File "/home/airflow/.local/lib/python3.12/site-packages/MySQLdb/cursors.py", line 330, in _query
    db.query(q)
  File "/home/airflow/.local/lib/python3.12/site-packages/MySQLdb/connections.py", line 261, in query
    _mysql.connection.query(self, query)
MySQLdb.OperationalError: (1046, 'No database selected')

The above exception was the direct cause of the following exception:

Traceback (most recent call last):
  File "/home/airflow/.local/lib/python3.12/site-packages/airflow/models/taskinstance.py", line 465, in _execute_task
    result = _execute_callable(context=context, **execute_callable_kwargs)
             ^^^^^^^^^^^^^^^^^^^^^^^^^^^^^^^^^^^^^^^^^^^^^^^^^^^^^^^^^^^^^
  File "/home/airflow/.local/lib/python3.12/site-packages/airflow/models/taskinstance.py", line 432, in _execute_callable
    return execute_callable(context=context, **execute_callable_kwargs)
           ^^^^^^^^^^^^^^^^^^^^^^^^^^^^^^^^^^^^^^^^^^^^^^^^^^^^^^^^^^^^
  File "/home/airflow/.local/lib/python3.12/site-packages/airflow/models/baseoperator.py", line 401, in wrapper
    return func(self, *args, **kwargs)
           ^^^^^^^^^^^^^^^^^^^^^^^^^^^
  File "/home/airflow/.local/lib/python3.12/site-packages/airflow/operators/python.py", line 235, in execute
    return_value = self.execute_callable()
                   ^^^^^^^^^^^^^^^^^^^^^^^
  File "/home/airflow/.local/lib/python3.12/site-packages/airflow/operators/python.py", line 252, in execute_callable
    return self.python_callable(*self.op_args, **self.op_kwargs)
           ^^^^^^^^^^^^^^^^^^^^^^^^^^^^^^^^^^^^^^^^^^^^^^^^^^^^^
  File "/opt/airflow/dags/data_transfer_dag.py", line 15, in load_data_to_mysql
    df.to_sql('users', con=engine, if_exists='replace', index=False)
  File "/home/airflow/.local/lib/python3.12/site-packages/pandas/util/_decorators.py", line 333, in wrapper
    return func(*args, **kwargs)
           ^^^^^^^^^^^^^^^^^^^^^
  File "/home/airflow/.local/lib/python3.12/site-packages/pandas/core/generic.py", line 3008, in to_sql
    return sql.to_sql(
           ^^^^^^^^^^^
  File "/home/airflow/.local/lib/python3.12/site-packages/pandas/io/sql.py", line 788, in to_sql
    return pandas_sql.to_sql(
           ^^^^^^^^^^^^^^^^^^
  File "/home/airflow/.local/lib/python3.12/site-packages/pandas/io/sql.py", line 1948, in to_sql
    table = self.prep_table(
            ^^^^^^^^^^^^^^^^
  File "/home/airflow/.local/lib/python3.12/site-packages/pandas/io/sql.py", line 1852, in prep_table
    table.create()
  File "/home/airflow/.local/lib/python3.12/site-packages/pandas/io/sql.py", line 936, in create
    self._execute_create()
  File "/home/airflow/.local/lib/python3.12/site-packages/pandas/io/sql.py", line 922, in _execute_create
    self.table.create(bind=self.pd_sql.con)
  File "/home/airflow/.local/lib/python3.12/site-packages/sqlalchemy/sql/schema.py", line 962, in create
    bind._run_ddl_visitor(ddl.SchemaGenerator, self, checkfirst=checkfirst)
  File "/home/airflow/.local/lib/python3.12/site-packages/sqlalchemy/engine/base.py", line 2221, in _run_ddl_visitor
    visitorcallable(self.dialect, self, **kwargs).traverse_single(element)
  File "/home/airflow/.local/lib/python3.12/site-packages/sqlalchemy/sql/visitors.py", line 524, in traverse_single
    return meth(obj, **kw)
           ^^^^^^^^^^^^^^^
  File "/home/airflow/.local/lib/python3.12/site-packages/sqlalchemy/sql/ddl.py", line 899, in visit_table
    self.connection.execute(
  File "/home/airflow/.local/lib/python3.12/site-packages/sqlalchemy/engine/base.py", line 1385, in execute
    return meth(self, multiparams, params, _EMPTY_EXECUTION_OPTS)
           ^^^^^^^^^^^^^^^^^^^^^^^^^^^^^^^^^^^^^^^^^^^^^^^^^^^^^^
  File "/home/airflow/.local/lib/python3.12/site-packages/sqlalchemy/sql/ddl.py", line 80, in _execute_on_connection
    return connection._execute_ddl(
           ^^^^^^^^^^^^^^^^^^^^^^^^
  File "/home/airflow/.local/lib/python3.12/site-packages/sqlalchemy/engine/base.py", line 1477, in _execute_ddl
    ret = self._execute_context(
          ^^^^^^^^^^^^^^^^^^^^^^
  File "/home/airflow/.local/lib/python3.12/site-packages/sqlalchemy/engine/base.py", line 1953, in _execute_context
    self._handle_dbapi_exception(
  File "/home/airflow/.local/lib/python3.12/site-packages/sqlalchemy/engine/base.py", line 2134, in _handle_dbapi_exception
    util.raise_(
  File "/home/airflow/.local/lib/python3.12/site-packages/sqlalchemy/util/compat.py", line 211, in raise_
    raise exception
  File "/home/airflow/.local/lib/python3.12/site-packages/sqlalchemy/engine/base.py", line 1910, in _execute_context
    self.dialect.do_execute(
  File "/home/airflow/.local/lib/python3.12/site-packages/sqlalchemy/engine/default.py", line 736, in do_execute
    cursor.execute(statement, parameters)
  File "/home/airflow/.local/lib/python3.12/site-packages/MySQLdb/cursors.py", line 179, in execute
    res = self._query(mogrified_query)
          ^^^^^^^^^^^^^^^^^^^^^^^^^^^^
  File "/home/airflow/.local/lib/python3.12/site-packages/MySQLdb/cursors.py", line 330, in _query
    db.query(q)
  File "/home/airflow/.local/lib/python3.12/site-packages/MySQLdb/connections.py", line 261, in query
    _mysql.connection.query(self, query)
sqlalchemy.exc.OperationalError: (MySQLdb.OperationalError) (1046, 'No database selected')
[SQL: 
CREATE TABLE users (
	id BIGINT, 
	name TEXT, 
	email TEXT
)

]
(Background on this error at: https://sqlalche.me/e/14/e3q8)
[2024-06-26T15:35:15.093+0000] {taskinstance.py:1206} INFO - Marking task as UP_FOR_RETRY. dag_id=data_transfer_to_mysql, task_id=load_data_to_mysql, run_id=manual__2024-06-26T15:35:14.290955+00:00, execution_date=20240626T153514, start_date=20240626T153514, end_date=20240626T153515
[2024-06-26T15:35:15.099+0000] {standard_task_runner.py:110} ERROR - Failed to execute job 35 for task load_data_to_mysql ((MySQLdb.OperationalError) (1046, 'No database selected')
[SQL: 
CREATE TABLE users (
	id BIGINT, 
	name TEXT, 
	email TEXT
)

]
(Background on this error at: https://sqlalche.me/e/14/e3q8); 668)
[2024-06-26T15:35:15.128+0000] {local_task_job_runner.py:240} INFO - Task exited with return code 1
[2024-06-26T15:35:15.149+0000] {taskinstance.py:3503} INFO - 0 downstream tasks scheduled from follow-on schedule check
[2024-06-26T15:35:15.151+0000] {local_task_job_runner.py:222} INFO - ::endgroup::
