[2024-06-26T23:25:15.075+0000] {local_task_job_runner.py:120} INFO - ::group::Pre task execution logs
[2024-06-26T23:25:15.104+0000] {taskinstance.py:2076} INFO - Dependencies all met for dep_context=non-requeueable deps ti=<TaskInstance: data_backup_to_gcs.load_data_to_mysql manual__2024-06-26T23:18:11.102531+00:00 [queued]>
[2024-06-26T23:25:15.110+0000] {taskinstance.py:2076} INFO - Dependencies all met for dep_context=requeueable deps ti=<TaskInstance: data_backup_to_gcs.load_data_to_mysql manual__2024-06-26T23:18:11.102531+00:00 [queued]>
[2024-06-26T23:25:15.111+0000] {taskinstance.py:2306} INFO - Starting attempt 1 of 2
[2024-06-26T23:25:15.119+0000] {taskinstance.py:2330} INFO - Executing <Task(PythonOperator): load_data_to_mysql> on 2024-06-26 23:18:11.102531+00:00
[2024-06-26T23:25:15.127+0000] {logging_mixin.py:188} WARNING - /home/***/.local/lib/python3.12/site-packages/***/task/task_runner/standard_task_runner.py:61 DeprecationWarning: This process (pid=699) is multi-threaded, use of fork() may lead to deadlocks in the child.
[2024-06-26T23:25:15.128+0000] {standard_task_runner.py:63} INFO - Started process 706 to run task
[2024-06-26T23:25:15.126+0000] {standard_task_runner.py:90} INFO - Running: ['***', 'tasks', 'run', 'data_backup_to_gcs', 'load_data_to_mysql', 'manual__2024-06-26T23:18:11.102531+00:00', '--job-id', '63', '--raw', '--subdir', 'DAGS_FOLDER/to_gcs.py', '--cfg-path', '/tmp/tmpvxw1t3pt']
[2024-06-26T23:25:15.128+0000] {standard_task_runner.py:91} INFO - Job 63: Subtask load_data_to_mysql
[2024-06-26T23:25:15.161+0000] {task_command.py:426} INFO - Running <TaskInstance: data_backup_to_gcs.load_data_to_mysql manual__2024-06-26T23:18:11.102531+00:00 [running]> on host 1156a65a130e
[2024-06-26T23:25:15.219+0000] {taskinstance.py:2648} INFO - Exporting env vars: AIRFLOW_CTX_DAG_OWNER='***' AIRFLOW_CTX_DAG_ID='data_backup_to_gcs' AIRFLOW_CTX_TASK_ID='load_data_to_mysql' AIRFLOW_CTX_EXECUTION_DATE='2024-06-26T23:18:11.102531+00:00' AIRFLOW_CTX_TRY_NUMBER='1' AIRFLOW_CTX_DAG_RUN_ID='manual__2024-06-26T23:18:11.102531+00:00'
[2024-06-26T23:25:15.219+0000] {taskinstance.py:430} INFO - ::endgroup::
[2024-06-26T23:25:15.235+0000] {base.py:84} INFO - Using connection ID 'mysql_conn' for task execution.
[2024-06-26T23:25:15.236+0000] {taskinstance.py:441} INFO - ::group::Post task execution logs
[2024-06-26T23:25:15.236+0000] {taskinstance.py:2905} ERROR - Task failed with exception
Traceback (most recent call last):
  File "/home/airflow/.local/lib/python3.12/site-packages/airflow/models/taskinstance.py", line 465, in _execute_task
    result = _execute_callable(context=context, **execute_callable_kwargs)
             ^^^^^^^^^^^^^^^^^^^^^^^^^^^^^^^^^^^^^^^^^^^^^^^^^^^^^^^^^^^^^
  File "/home/airflow/.local/lib/python3.12/site-packages/airflow/models/taskinstance.py", line 432, in _execute_callable
    return execute_callable(context=context, **execute_callable_kwargs)
           ^^^^^^^^^^^^^^^^^^^^^^^^^^^^^^^^^^^^^^^^^^^^^^^^^^^^^^^^^^^^
  File "/home/airflow/.local/lib/python3.12/site-packages/airflow/models/baseoperator.py", line 401, in wrapper
    return func(self, *args, **kwargs)
           ^^^^^^^^^^^^^^^^^^^^^^^^^^^
  File "/home/airflow/.local/lib/python3.12/site-packages/airflow/operators/python.py", line 235, in execute
    return_value = self.execute_callable()
                   ^^^^^^^^^^^^^^^^^^^^^^^
  File "/home/airflow/.local/lib/python3.12/site-packages/airflow/operators/python.py", line 252, in execute_callable
    return self.python_callable(*self.op_args, **self.op_kwargs)
           ^^^^^^^^^^^^^^^^^^^^^^^^^^^^^^^^^^^^^^^^^^^^^^^^^^^^^
  File "/opt/airflow/dags/to_gcs.py", line 13, in load_data_to_mysql
    engine = create_engine(hook.get_uri().replace('mysql://', 'mysql+pymysql://'))  # Menggunakan SQLAlchemy untuk menghubungkan
             ^^^^^^^^^^^^^^^^^^^^^^^^^^^^^^^^^^^^^^^^^^^^^^^^^^^^^^^^^^^^^^^^^^^^^
  File "<string>", line 2, in create_engine
  File "/home/airflow/.local/lib/python3.12/site-packages/sqlalchemy/util/deprecations.py", line 375, in warned
    return fn(*args, **kwargs)
           ^^^^^^^^^^^^^^^^^^^
  File "/home/airflow/.local/lib/python3.12/site-packages/sqlalchemy/engine/create.py", line 544, in create_engine
    dbapi = dialect_cls.dbapi(**dbapi_args)
            ^^^^^^^^^^^^^^^^^^^^^^^^^^^^^^^
  File "/home/airflow/.local/lib/python3.12/site-packages/sqlalchemy/dialects/mysql/pymysql.py", line 80, in dbapi
    return __import__("pymysql")
           ^^^^^^^^^^^^^^^^^^^^^
ModuleNotFoundError: No module named 'pymysql'
[2024-06-26T23:25:15.244+0000] {taskinstance.py:1206} INFO - Marking task as UP_FOR_RETRY. dag_id=data_backup_to_gcs, task_id=load_data_to_mysql, run_id=manual__2024-06-26T23:18:11.102531+00:00, execution_date=20240626T231811, start_date=20240626T232515, end_date=20240626T232515
[2024-06-26T23:25:15.252+0000] {standard_task_runner.py:110} ERROR - Failed to execute job 63 for task load_data_to_mysql (No module named 'pymysql'; 706)
[2024-06-26T23:25:15.261+0000] {local_task_job_runner.py:240} INFO - Task exited with return code 1
[2024-06-26T23:25:15.282+0000] {taskinstance.py:3503} INFO - 0 downstream tasks scheduled from follow-on schedule check
[2024-06-26T23:25:15.283+0000] {local_task_job_runner.py:222} INFO - ::endgroup::
