[2024-06-26T23:20:07.856+0000] {local_task_job_runner.py:120} INFO - ::group::Pre task execution logs
[2024-06-26T23:20:07.878+0000] {taskinstance.py:2076} INFO - Dependencies all met for dep_context=non-requeueable deps ti=<TaskInstance: data_backup_to_gcs.backup_mysql scheduled__2024-06-25T00:00:00+00:00 [queued]>
[2024-06-26T23:20:07.885+0000] {taskinstance.py:2076} INFO - Dependencies all met for dep_context=requeueable deps ti=<TaskInstance: data_backup_to_gcs.backup_mysql scheduled__2024-06-25T00:00:00+00:00 [queued]>
[2024-06-26T23:20:07.885+0000] {taskinstance.py:2306} INFO - Starting attempt 2 of 2
[2024-06-26T23:20:07.893+0000] {taskinstance.py:2330} INFO - Executing <Task(BashOperator): backup_mysql> on 2024-06-25 00:00:00+00:00
[2024-06-26T23:20:07.903+0000] {standard_task_runner.py:90} INFO - Running: ['***', 'tasks', 'run', 'data_backup_to_gcs', 'backup_mysql', 'scheduled__2024-06-25T00:00:00+00:00', '--job-id', '55', '--raw', '--subdir', 'DAGS_FOLDER/to_gcs.py', '--cfg-path', '/tmp/tmp616x05sw']
[2024-06-26T23:20:07.905+0000] {standard_task_runner.py:91} INFO - Job 55: Subtask backup_mysql
[2024-06-26T23:20:07.906+0000] {logging_mixin.py:188} WARNING - /home/***/.local/lib/python3.12/site-packages/***/task/task_runner/standard_task_runner.py:61 DeprecationWarning: This process (pid=528) is multi-threaded, use of fork() may lead to deadlocks in the child.
[2024-06-26T23:20:07.907+0000] {standard_task_runner.py:63} INFO - Started process 533 to run task
[2024-06-26T23:20:07.948+0000] {task_command.py:426} INFO - Running <TaskInstance: data_backup_to_gcs.backup_mysql scheduled__2024-06-25T00:00:00+00:00 [running]> on host 1156a65a130e
[2024-06-26T23:20:08.017+0000] {taskinstance.py:2648} INFO - Exporting env vars: AIRFLOW_CTX_DAG_OWNER='***' AIRFLOW_CTX_DAG_ID='data_backup_to_gcs' AIRFLOW_CTX_TASK_ID='backup_mysql' AIRFLOW_CTX_EXECUTION_DATE='2024-06-25T00:00:00+00:00' AIRFLOW_CTX_TRY_NUMBER='2' AIRFLOW_CTX_DAG_RUN_ID='scheduled__2024-06-25T00:00:00+00:00'
[2024-06-26T23:20:08.018+0000] {taskinstance.py:430} INFO - ::endgroup::
[2024-06-26T23:20:08.024+0000] {subprocess.py:63} INFO - Tmp dir root location: /tmp
[2024-06-26T23:20:08.025+0000] {subprocess.py:75} INFO - Running command: ['/usr/bin/bash', '-c', 'mysqldump -h mysql-db -u root -ppassword dataset_db > /opt/***/dags/backup.sql']
[2024-06-26T23:20:08.034+0000] {subprocess.py:86} INFO - Output:
[2024-06-26T23:20:41.630+0000] {subprocess.py:93} INFO - mysqldump: Got error: 2005: "Unknown server host 'mysql-db' (-3)" when trying to connect
[2024-06-26T23:20:41.632+0000] {subprocess.py:97} INFO - Command exited with return code 2
[2024-06-26T23:20:41.634+0000] {taskinstance.py:441} INFO - ::group::Post task execution logs
[2024-06-26T23:20:41.658+0000] {taskinstance.py:2905} ERROR - Task failed with exception
Traceback (most recent call last):
  File "/home/airflow/.local/lib/python3.12/site-packages/airflow/models/taskinstance.py", line 465, in _execute_task
    result = _execute_callable(context=context, **execute_callable_kwargs)
             ^^^^^^^^^^^^^^^^^^^^^^^^^^^^^^^^^^^^^^^^^^^^^^^^^^^^^^^^^^^^^
  File "/home/airflow/.local/lib/python3.12/site-packages/airflow/models/taskinstance.py", line 432, in _execute_callable
    return execute_callable(context=context, **execute_callable_kwargs)
           ^^^^^^^^^^^^^^^^^^^^^^^^^^^^^^^^^^^^^^^^^^^^^^^^^^^^^^^^^^^^
  File "/home/airflow/.local/lib/python3.12/site-packages/airflow/models/baseoperator.py", line 401, in wrapper
    return func(self, *args, **kwargs)
           ^^^^^^^^^^^^^^^^^^^^^^^^^^^
  File "/home/airflow/.local/lib/python3.12/site-packages/airflow/operators/bash.py", line 243, in execute
    raise AirflowException(
airflow.exceptions.AirflowException: Bash command failed. The command returned a non-zero exit code 2.
[2024-06-26T23:20:41.666+0000] {taskinstance.py:1206} INFO - Marking task as FAILED. dag_id=data_backup_to_gcs, task_id=backup_mysql, run_id=scheduled__2024-06-25T00:00:00+00:00, execution_date=20240625T000000, start_date=20240626T232007, end_date=20240626T232041
[2024-06-26T23:20:41.677+0000] {standard_task_runner.py:110} ERROR - Failed to execute job 55 for task backup_mysql (Bash command failed. The command returned a non-zero exit code 2.; 533)
[2024-06-26T23:20:41.724+0000] {local_task_job_runner.py:240} INFO - Task exited with return code 1
[2024-06-26T23:20:41.756+0000] {taskinstance.py:3503} INFO - 0 downstream tasks scheduled from follow-on schedule check
[2024-06-26T23:20:41.760+0000] {local_task_job_runner.py:222} INFO - ::endgroup::
