[2024-06-27T00:00:02.308+0000] {local_task_job_runner.py:120} INFO - ::group::Pre task execution logs
[2024-06-27T00:00:02.340+0000] {taskinstance.py:2076} INFO - Dependencies all met for dep_context=non-requeueable deps ti=<TaskInstance: data_backup_to_gcs.backup_mysql scheduled__2024-06-26T00:00:00+00:00 [queued]>
[2024-06-27T00:00:02.348+0000] {taskinstance.py:2076} INFO - Dependencies all met for dep_context=requeueable deps ti=<TaskInstance: data_backup_to_gcs.backup_mysql scheduled__2024-06-26T00:00:00+00:00 [queued]>
[2024-06-27T00:00:02.349+0000] {taskinstance.py:2306} INFO - Starting attempt 1 of 2
[2024-06-27T00:00:02.362+0000] {taskinstance.py:2330} INFO - Executing <Task(BashOperator): backup_mysql> on 2024-06-26 00:00:00+00:00
[2024-06-27T00:00:02.370+0000] {logging_mixin.py:188} WARNING - /home/***/.local/lib/python3.12/site-packages/***/task/task_runner/standard_task_runner.py:61 DeprecationWarning: This process (pid=1617) is multi-threaded, use of fork() may lead to deadlocks in the child.
[2024-06-27T00:00:02.370+0000] {standard_task_runner.py:63} INFO - Started process 1619 to run task
[2024-06-27T00:00:02.371+0000] {standard_task_runner.py:90} INFO - Running: ['***', 'tasks', 'run', 'data_backup_to_gcs', 'backup_mysql', 'scheduled__2024-06-26T00:00:00+00:00', '--job-id', '84', '--raw', '--subdir', 'DAGS_FOLDER/to_gcs.py', '--cfg-path', '/tmp/tmpzfnj1lmd']
[2024-06-27T00:00:02.372+0000] {standard_task_runner.py:91} INFO - Job 84: Subtask backup_mysql
[2024-06-27T00:00:02.423+0000] {task_command.py:426} INFO - Running <TaskInstance: data_backup_to_gcs.backup_mysql scheduled__2024-06-26T00:00:00+00:00 [running]> on host 1156a65a130e
[2024-06-27T00:00:02.519+0000] {taskinstance.py:2648} INFO - Exporting env vars: AIRFLOW_CTX_DAG_OWNER='***' AIRFLOW_CTX_DAG_ID='data_backup_to_gcs' AIRFLOW_CTX_TASK_ID='backup_mysql' AIRFLOW_CTX_EXECUTION_DATE='2024-06-26T00:00:00+00:00' AIRFLOW_CTX_TRY_NUMBER='1' AIRFLOW_CTX_DAG_RUN_ID='scheduled__2024-06-26T00:00:00+00:00'
[2024-06-27T00:00:02.520+0000] {taskinstance.py:430} INFO - ::endgroup::
[2024-06-27T00:00:02.533+0000] {subprocess.py:63} INFO - Tmp dir root location: /tmp
[2024-06-27T00:00:02.533+0000] {subprocess.py:75} INFO - Running command: ['/usr/bin/bash', '-c', 'mysqldump -h mysql-db -u root -ppassword dataset_db > /opt/***/dags/backup.sql']
[2024-06-27T00:00:02.546+0000] {subprocess.py:86} INFO - Output:
[2024-06-27T00:00:08.207+0000] {local_task_job_runner.py:124} ERROR - Received SIGTERM. Terminating subprocesses
[2024-06-27T00:00:08.210+0000] {process_utils.py:132} INFO - Sending 15 to group 1619. PIDs of all processes in the group: [1620, 1621, 1619]
[2024-06-27T00:00:08.211+0000] {process_utils.py:87} INFO - Sending the signal 15 to group 1619
[2024-06-27T00:00:08.212+0000] {taskinstance.py:2611} ERROR - Received SIGTERM. Terminating subprocesses.
[2024-06-27T00:00:08.212+0000] {subprocess.py:104} INFO - Sending SIGTERM signal to process group
[2024-06-27T00:00:08.212+0000] {taskinstance.py:441} INFO - ::group::Post task execution logs
[2024-06-27T00:00:08.226+0000] {taskinstance.py:2905} ERROR - Task failed with exception
Traceback (most recent call last):
  File "/home/airflow/.local/lib/python3.12/site-packages/airflow/models/taskinstance.py", line 465, in _execute_task
    result = _execute_callable(context=context, **execute_callable_kwargs)
             ^^^^^^^^^^^^^^^^^^^^^^^^^^^^^^^^^^^^^^^^^^^^^^^^^^^^^^^^^^^^^
  File "/home/airflow/.local/lib/python3.12/site-packages/airflow/models/taskinstance.py", line 432, in _execute_callable
    return execute_callable(context=context, **execute_callable_kwargs)
           ^^^^^^^^^^^^^^^^^^^^^^^^^^^^^^^^^^^^^^^^^^^^^^^^^^^^^^^^^^^^
  File "/home/airflow/.local/lib/python3.12/site-packages/airflow/models/baseoperator.py", line 401, in wrapper
    return func(self, *args, **kwargs)
           ^^^^^^^^^^^^^^^^^^^^^^^^^^^
  File "/home/airflow/.local/lib/python3.12/site-packages/airflow/operators/bash.py", line 234, in execute
    result = self.subprocess_hook.run_command(
             ^^^^^^^^^^^^^^^^^^^^^^^^^^^^^^^^^
  File "/home/airflow/.local/lib/python3.12/site-packages/airflow/hooks/subprocess.py", line 91, in run_command
    for raw_line in iter(self.sub_process.stdout.readline, b""):
  File "/home/airflow/.local/lib/python3.12/site-packages/airflow/models/taskinstance.py", line 2613, in signal_handler
    raise AirflowTaskTerminated("Task received SIGTERM signal")
airflow.exceptions.AirflowTaskTerminated: Task received SIGTERM signal
[2024-06-27T00:00:08.231+0000] {taskinstance.py:1206} INFO - Marking task as UP_FOR_RETRY. dag_id=data_backup_to_gcs, task_id=backup_mysql, run_id=scheduled__2024-06-26T00:00:00+00:00, execution_date=20240626T000000, start_date=20240627T000002, end_date=20240627T000008
[2024-06-27T00:00:08.269+0000] {process_utils.py:80} INFO - Process psutil.Process(pid=1619, status='terminated', exitcode=2, started='00:00:01') (1619) terminated with exit code 2
[2024-06-27T00:00:08.270+0000] {process_utils.py:80} INFO - Process psutil.Process(pid=1620, status='terminated', started='00:00:02') (1620) terminated with exit code None
[2024-06-27T00:00:08.270+0000] {process_utils.py:80} INFO - Process psutil.Process(pid=1621, status='terminated', started='00:00:02') (1621) terminated with exit code None
[2024-06-27T00:00:08.271+0000] {local_task_job_runner.py:240} INFO - Task exited with return code 143
[2024-06-27T00:00:08.303+0000] {taskinstance.py:3503} INFO - 0 downstream tasks scheduled from follow-on schedule check
