[2024-06-27T00:15:48.917+0000] {local_task_job_runner.py:120} INFO - ::group::Pre task execution logs
[2024-06-27T00:15:48.942+0000] {taskinstance.py:2076} INFO - Dependencies all met for dep_context=non-requeueable deps ti=<TaskInstance: data_backup_to_gcs.backup_mysql scheduled__2024-06-26T00:00:00+00:00 [queued]>
[2024-06-27T00:15:48.949+0000] {taskinstance.py:2076} INFO - Dependencies all met for dep_context=requeueable deps ti=<TaskInstance: data_backup_to_gcs.backup_mysql scheduled__2024-06-26T00:00:00+00:00 [queued]>
[2024-06-27T00:15:48.949+0000] {taskinstance.py:2306} INFO - Starting attempt 2 of 2
[2024-06-27T00:15:48.957+0000] {taskinstance.py:2330} INFO - Executing <Task(BashOperator): backup_mysql> on 2024-06-26 00:00:00+00:00
[2024-06-27T00:15:48.965+0000] {logging_mixin.py:188} WARNING - /home/***/.local/lib/python3.12/site-packages/***/task/task_runner/standard_task_runner.py:61 DeprecationWarning: This process (pid=204) is multi-threaded, use of fork() may lead to deadlocks in the child.
[2024-06-27T00:15:48.963+0000] {standard_task_runner.py:90} INFO - Running: ['***', 'tasks', 'run', 'data_backup_to_gcs', 'backup_mysql', 'scheduled__2024-06-26T00:00:00+00:00', '--job-id', '86', '--raw', '--subdir', 'DAGS_FOLDER/to_gcs.py', '--cfg-path', '/tmp/tmprg3plcv8']
[2024-06-27T00:15:48.965+0000] {standard_task_runner.py:63} INFO - Started process 209 to run task
[2024-06-27T00:15:48.965+0000] {standard_task_runner.py:91} INFO - Job 86: Subtask backup_mysql
[2024-06-27T00:15:48.998+0000] {task_command.py:426} INFO - Running <TaskInstance: data_backup_to_gcs.backup_mysql scheduled__2024-06-26T00:00:00+00:00 [running]> on host 7efb2309a0a3
[2024-06-27T00:15:49.061+0000] {taskinstance.py:2648} INFO - Exporting env vars: AIRFLOW_CTX_DAG_OWNER='***' AIRFLOW_CTX_DAG_ID='data_backup_to_gcs' AIRFLOW_CTX_TASK_ID='backup_mysql' AIRFLOW_CTX_EXECUTION_DATE='2024-06-26T00:00:00+00:00' AIRFLOW_CTX_TRY_NUMBER='2' AIRFLOW_CTX_DAG_RUN_ID='scheduled__2024-06-26T00:00:00+00:00'
[2024-06-27T00:15:49.062+0000] {taskinstance.py:430} INFO - ::endgroup::
[2024-06-27T00:15:49.084+0000] {subprocess.py:63} INFO - Tmp dir root location: /tmp
[2024-06-27T00:15:49.084+0000] {subprocess.py:75} INFO - Running command: ['/usr/bin/bash', '-c', 'mysqldump -h mysql-db -u root -ppassword dataset_db > /opt/***/dags/backup.sql']
[2024-06-27T00:15:49.093+0000] {subprocess.py:86} INFO - Output:
[2024-06-27T00:16:22.676+0000] {subprocess.py:93} INFO - mysqldump: Got error: 2005: "Unknown server host 'mysql-db' (-3)" when trying to connect
[2024-06-27T00:16:22.677+0000] {subprocess.py:97} INFO - Command exited with return code 2
[2024-06-27T00:16:22.677+0000] {taskinstance.py:441} INFO - ::group::Post task execution logs
[2024-06-27T00:16:22.688+0000] {taskinstance.py:2905} ERROR - Task failed with exception
Traceback (most recent call last):
  File "/home/airflow/.local/lib/python3.12/site-packages/airflow/models/taskinstance.py", line 465, in _execute_task
    result = _execute_callable(context=context, **execute_callable_kwargs)
             ^^^^^^^^^^^^^^^^^^^^^^^^^^^^^^^^^^^^^^^^^^^^^^^^^^^^^^^^^^^^^
  File "/home/airflow/.local/lib/python3.12/site-packages/airflow/models/taskinstance.py", line 432, in _execute_callable
    return execute_callable(context=context, **execute_callable_kwargs)
           ^^^^^^^^^^^^^^^^^^^^^^^^^^^^^^^^^^^^^^^^^^^^^^^^^^^^^^^^^^^^
  File "/home/airflow/.local/lib/python3.12/site-packages/airflow/models/baseoperator.py", line 401, in wrapper
    return func(self, *args, **kwargs)
           ^^^^^^^^^^^^^^^^^^^^^^^^^^^
  File "/home/airflow/.local/lib/python3.12/site-packages/airflow/operators/bash.py", line 243, in execute
    raise AirflowException(
airflow.exceptions.AirflowException: Bash command failed. The command returned a non-zero exit code 2.
[2024-06-27T00:16:22.694+0000] {taskinstance.py:1206} INFO - Marking task as FAILED. dag_id=data_backup_to_gcs, task_id=backup_mysql, run_id=scheduled__2024-06-26T00:00:00+00:00, execution_date=20240626T000000, start_date=20240627T001548, end_date=20240627T001622
[2024-06-27T00:16:22.710+0000] {standard_task_runner.py:110} ERROR - Failed to execute job 86 for task backup_mysql (Bash command failed. The command returned a non-zero exit code 2.; 209)
[2024-06-27T00:16:22.750+0000] {local_task_job_runner.py:240} INFO - Task exited with return code 1
[2024-06-27T00:16:22.785+0000] {taskinstance.py:3503} INFO - 0 downstream tasks scheduled from follow-on schedule check
[2024-06-27T00:16:22.789+0000] {local_task_job_runner.py:222} INFO - ::endgroup::
