[2024-06-26T22:14:43.273+0000] {local_task_job_runner.py:120} INFO - ::group::Pre task execution logs
[2024-06-26T22:14:43.299+0000] {taskinstance.py:2076} INFO - Dependencies all met for dep_context=non-requeueable deps ti=<TaskInstance: data_transfer_to_mysql.load_data_to_mysql manual__2024-06-26T22:14:42.844274+00:00 [queued]>
[2024-06-26T22:14:43.305+0000] {taskinstance.py:2076} INFO - Dependencies all met for dep_context=requeueable deps ti=<TaskInstance: data_transfer_to_mysql.load_data_to_mysql manual__2024-06-26T22:14:42.844274+00:00 [queued]>
[2024-06-26T22:14:43.305+0000] {taskinstance.py:2306} INFO - Starting attempt 1 of 2
[2024-06-26T22:14:43.320+0000] {taskinstance.py:2330} INFO - Executing <Task(PythonOperator): load_data_to_mysql> on 2024-06-26 22:14:42.844274+00:00
[2024-06-26T22:14:43.329+0000] {standard_task_runner.py:90} INFO - Running: ['***', 'tasks', 'run', 'data_transfer_to_mysql', 'load_data_to_mysql', 'manual__2024-06-26T22:14:42.844274+00:00', '--job-id', '39', '--raw', '--subdir', 'DAGS_FOLDER/data_transfer_dag.py', '--cfg-path', '/tmp/tmpi4f0mhjn']
[2024-06-26T22:14:43.331+0000] {logging_mixin.py:188} WARNING - /home/***/.local/lib/python3.12/site-packages/***/task/task_runner/standard_task_runner.py:61 DeprecationWarning: This process (pid=840) is multi-threaded, use of fork() may lead to deadlocks in the child.
[2024-06-26T22:14:43.331+0000] {standard_task_runner.py:63} INFO - Started process 842 to run task
[2024-06-26T22:14:43.331+0000] {standard_task_runner.py:91} INFO - Job 39: Subtask load_data_to_mysql
[2024-06-26T22:14:43.371+0000] {task_command.py:426} INFO - Running <TaskInstance: data_transfer_to_mysql.load_data_to_mysql manual__2024-06-26T22:14:42.844274+00:00 [running]> on host fa313e9b9eb9
[2024-06-26T22:14:43.488+0000] {taskinstance.py:2648} INFO - Exporting env vars: AIRFLOW_CTX_DAG_OWNER='***' AIRFLOW_CTX_DAG_ID='data_transfer_to_mysql' AIRFLOW_CTX_TASK_ID='load_data_to_mysql' AIRFLOW_CTX_EXECUTION_DATE='2024-06-26T22:14:42.844274+00:00' AIRFLOW_CTX_TRY_NUMBER='1' AIRFLOW_CTX_DAG_RUN_ID='manual__2024-06-26T22:14:42.844274+00:00'
[2024-06-26T22:14:43.490+0000] {taskinstance.py:430} INFO - ::endgroup::
[2024-06-26T22:14:43.520+0000] {base.py:84} INFO - Using connection ID 'mysql_conn' for task execution.
[2024-06-26T22:14:43.524+0000] {taskinstance.py:441} INFO - ::group::Post task execution logs
[2024-06-26T22:14:43.525+0000] {taskinstance.py:2905} ERROR - Task failed with exception
Traceback (most recent call last):
  File "/home/airflow/.local/lib/python3.12/site-packages/airflow/models/taskinstance.py", line 465, in _execute_task
    result = _execute_callable(context=context, **execute_callable_kwargs)
             ^^^^^^^^^^^^^^^^^^^^^^^^^^^^^^^^^^^^^^^^^^^^^^^^^^^^^^^^^^^^^
  File "/home/airflow/.local/lib/python3.12/site-packages/airflow/models/taskinstance.py", line 432, in _execute_callable
    return execute_callable(context=context, **execute_callable_kwargs)
           ^^^^^^^^^^^^^^^^^^^^^^^^^^^^^^^^^^^^^^^^^^^^^^^^^^^^^^^^^^^^
  File "/home/airflow/.local/lib/python3.12/site-packages/airflow/models/baseoperator.py", line 401, in wrapper
    return func(self, *args, **kwargs)
           ^^^^^^^^^^^^^^^^^^^^^^^^^^^
  File "/home/airflow/.local/lib/python3.12/site-packages/airflow/operators/python.py", line 235, in execute
    return_value = self.execute_callable()
                   ^^^^^^^^^^^^^^^^^^^^^^^
  File "/home/airflow/.local/lib/python3.12/site-packages/airflow/operators/python.py", line 252, in execute_callable
    return self.python_callable(*self.op_args, **self.op_kwargs)
           ^^^^^^^^^^^^^^^^^^^^^^^^^^^^^^^^^^^^^^^^^^^^^^^^^^^^^
  File "/opt/airflow/dags/data_transfer_dag.py", line 13, in load_data_to_mysql
    df = pd.read_csv('/opt/airflow/dags/data/dags/data/online_gaming_behavior_dataset.csv')
         ^^^^^^^^^^^^^^^^^^^^^^^^^^^^^^^^^^^^^^^^^^^^^^^^^^^^^^^^^^^^^^^^^^^^^^^^^^^^^^^^^^
  File "/home/airflow/.local/lib/python3.12/site-packages/pandas/io/parsers/readers.py", line 948, in read_csv
    return _read(filepath_or_buffer, kwds)
           ^^^^^^^^^^^^^^^^^^^^^^^^^^^^^^^
  File "/home/airflow/.local/lib/python3.12/site-packages/pandas/io/parsers/readers.py", line 611, in _read
    parser = TextFileReader(filepath_or_buffer, **kwds)
             ^^^^^^^^^^^^^^^^^^^^^^^^^^^^^^^^^^^^^^^^^^
  File "/home/airflow/.local/lib/python3.12/site-packages/pandas/io/parsers/readers.py", line 1448, in __init__
    self._engine = self._make_engine(f, self.engine)
                   ^^^^^^^^^^^^^^^^^^^^^^^^^^^^^^^^^
  File "/home/airflow/.local/lib/python3.12/site-packages/pandas/io/parsers/readers.py", line 1705, in _make_engine
    self.handles = get_handle(
                   ^^^^^^^^^^^
  File "/home/airflow/.local/lib/python3.12/site-packages/pandas/io/common.py", line 863, in get_handle
    handle = open(
             ^^^^^
FileNotFoundError: [Errno 2] No such file or directory: '/opt/airflow/dags/data/dags/data/online_gaming_behavior_dataset.csv'
[2024-06-26T22:14:43.541+0000] {taskinstance.py:1206} INFO - Marking task as UP_FOR_RETRY. dag_id=data_transfer_to_mysql, task_id=load_data_to_mysql, run_id=manual__2024-06-26T22:14:42.844274+00:00, execution_date=20240626T221442, start_date=20240626T221443, end_date=20240626T221443
[2024-06-26T22:14:43.554+0000] {standard_task_runner.py:110} ERROR - Failed to execute job 39 for task load_data_to_mysql ([Errno 2] No such file or directory: '/opt/airflow/dags/data/dags/data/online_gaming_behavior_dataset.csv'; 842)
[2024-06-26T22:14:43.584+0000] {local_task_job_runner.py:240} INFO - Task exited with return code 1
[2024-06-26T22:14:43.598+0000] {taskinstance.py:3503} INFO - 0 downstream tasks scheduled from follow-on schedule check
[2024-06-26T22:14:43.599+0000] {local_task_job_runner.py:222} INFO - ::endgroup::
